Workbook
Name __InitiativeName: "Kanban 7"
Name AP_Actuals: Summary!$U$5:$U$19
Name AP_Deliverables: 'Success Map'!$H$14:$K$28
Name AP_Est_Compressed: 'Success Map'!$O$14:$O$28
Name AP_Est_Normal: 'Success Map'!$M$14:$M$28
Name AP_Forecasts: Summary!$T$5:$T$19
Name AP_NextActions: Summary!$M$5:$P$19
Name AP_NextDates: Summary!$P$5:$P$19
Name AP_Owners: 'Success Map'!$L$14:$L$28
Name AP_Plans: Summary!$S$5:$S$19
Name AP_Start: 'Success Map'!$Q$11
Name B_Cadence: 'Success Map'!$I$46
Name B_Goal1: 'Success Map'!$F$47:$Q$47
Name B_Goal1Act: Summary!$J$46:$U$46
Name B_Goal1Fcst: Summary!$J$45:$U$45
Name B_Goal1Plan: 'Success Map'!$F$49:$Q$49
Name B_Goal1Sign: 'Success Map'!$Q$55
Name B_Goal2: 'Success Map'!$F$51:$Q$51
Name B_Goal2Act: Summary!$J$53:$U$53
Name B_Goal2Fcst: Summary!$J$52:$U$52
Name B_Goal2Plan: 'Success Map'!$F$53:$Q$53
Name B_Goal2Sign: 'Success Map'!$Q$56
Name B_Start: 'Success Map'!$F$46
Name B_Units: 'Success Map'!$J$46
Name Guide_Need: Summary!$C$6
Name Guide_NeedDate: Summary!$C$10
Name Guide_Owner: Summary!$C$12
Name Guide_Sponsor: Summary!$C$4
Name Guide_Team: Summary!$C$14
Name Pblm: Summary!$C$18
Name Pblm_CurrentPerf: Summary!$C$23
Name Pblm_Method: Summary!$C$29
Name Pblm_Metric: Summary!$C$21
Name Pblm_TargetPerf: Summary!$C$26
Name Soln: Summary!$C$38
Name Soln_CM1: Summary!$C$42
Name Soln_CM2: Summary!$C$46
Name Soln_CM3: Summary!$C$50
Name Soln_RC: Summary!$C$33
Name Status: Summary!$N$1
Name TT_Case1_Act: Summary!$L$26:$U$26
Name TT_Case1_Fcst: Summary!$L$25:$U$25
Name TT_Case1_Plan: 'Success Map'!$H$35:$Q$35
Name TT_Case2_Act: Summary!$L$30:$U$30
Name TT_Case2_Fcst: Summary!$L$29:$U$29
Name TT_Case2_Plan: 'Success Map'!$H$36:$Q$36
Name TT_Case3_Act: Summary!$L$33:$U$33
Name TT_Case3_Fcst: Summary!$L$33:$U$33
Name TT_Case3_Plan: 'Success Map'!$H$37:$Q$37
Name TT_Case4_Act: Summary!$L$37:$U$37
Name TT_Case4_Fcst: Summary!$L$37:$U$37
Name TT_Case4_Plan: 'Success Map'!$H$38:$Q$38
Name TT_Cases: 'Success Map'!$F$35:$G$38
Name TT_Laps: 'Success Map'!$F$34:$Q$34

Sheet Summary
A1: Initiative | B1: Install Kanban Task Board | M1: Status | N1: 4-Success Map tracking | P1: Last Update | Q1: 43446 | S1: Update Due
A2: Guide (Sponsor) | I2: Action Plan
A4: Sponsor | C4: Hannah | I4: Deliverable | M4: Next Action | P4: Date | Q4: Owner | R4: Plan | S4: Replan | T4: Fcst | U4: Actual
I5: =IF('Success Map'!H14="","",'Success Map'!H14) -> Define standard work for Kanban | Q5: =IF('Success Map'!L14="","",'Success Map'!L14) -> BB | R5: =IF('Success Map'!Q14="","",'Success Map'!Q14) -> 43791 | T5: 43791
A6: Explain Need | C6: Our team brings in a large number of small- and medium-sized tasks with no structured means to prioritize. This leads to systematic oversubscription, frustrating the team and disappointing internal customers | I6: =IF('Success Map'!H15="","",'Success Map'!H15) -> Pilot 1 | Q6: =IF('Success Map'!L15="","",'Success Map'!L15) -> Tucker | R6: =IF('Success Map'!Q15="","",'Success Map'!Q15) -> 43798 | T6: 43798
I7: =IF('Success Map'!H16="","",'Success Map'!H16) -> Pilot 2 | Q7: =IF('Success Map'!L16="","",'Success Map'!L16) -> Tucker | R7: =IF('Success Map'!Q16="","",'Success Map'!Q16) -> 43805 | T7: 43805
I8: =IF('Success Map'!H17="","",'Success Map'!H17) -> Train team | Q8: =IF('Success Map'!L17="","",'Success Map'!L17) -> BB | R8: =IF('Success Map'!Q17="","",'Success Map'!Q17) -> 43812 | T8: 43812
I9: =IF('Success Map'!H18="","",'Success Map'!H18) -> Define standard work for collecting rev by task | Q9: =IF('Success Map'!L18="","",'Success Map'!L18) -> BB | R9: =IF('Success Map'!Q18="","",'Success Map'!Q18) -> 43826 | T9: 43826
A10: Need-by date | C10: 2 months fully installed | I10: =IF('Success Map'!H19="","",'Success Map'!H19) -> Buffer | Q10: =IF('Success Map'!L19="","",'Success Map'!L19) | R10: =IF('Success Map'!Q19="","",'Success Map'!Q19) -> 43826 | T10: 43826
I11: =IF('Success Map'!H20="","",'Success Map'!H20) | Q11: =IF('Success Map'!L20="","",'Success Map'!L20) | R11: =IF('Success Map'!Q20="","",'Success Map'!Q20)
A12: Owner name | C12: Tucker | I12: =IF('Success Map'!H21="","",'Success Map'!H21) | Q12: =IF('Success Map'!L21="","",'Success Map'!L21) | R12: =IF('Success Map'!Q21="","",'Success Map'!Q21) | S12: =IF('Success Map'!P21="","",'Success Map'!P21)
I13: =IF('Success Map'!H22="","",'Success Map'!H22) | Q13: =IF('Success Map'!L22="","",'Success Map'!L22) | R13: =IF('Success Map'!Q22="","",'Success Map'!Q22) | S13: =IF('Success Map'!P22="","",'Success Map'!P22)
A14: Team members | C14: BB Johnson, Urs, Diego, Eyal | I14: =IF('Success Map'!H23="","",'Success Map'!H23) | Q14: =IF('Success Map'!L23="","",'Success Map'!L23) | R14: =IF('Success Map'!Q23="","",'Success Map'!Q23) | S14: =IF('Success Map'!P23="","",'Success Map'!P23)
I15: =IF('Success Map'!H24="","",'Success Map'!H24) | Q15: =IF('Success Map'!L24="","",'Success Map'!L24) | R15: =IF('Success Map'!Q24="","",'Success Map'!Q24) | S15: =IF('Success Map'!P24="","",'Success Map'!P24)
A16: Focus | I16: =IF('Success Map'!H25="","",'Success Map'!H25) | Q16: =IF('Success Map'!L25="","",'Success Map'!L25) | R16: =IF('Success Map'!Q25="","",'Success Map'!Q25) | S16: =IF('Success Map'!P25="","",'Success Map'!P25)
I17: =IF('Success Map'!H26="","",'Success Map'!H26) | Q17: =IF('Success Map'!L26="","",'Success Map'!L26) | R17: =IF('Success Map'!Q26="","",'Success Map'!Q26) | S17: =IF('Success Map'!P26="","",'Success Map'!P26)
A18: Problem or Opportunity | C18: Create global, single point of truth for task acceptance, prioritized by internal customers | I18: =IF('Success Map'!H27="","",'Success Map'!H27) | Q18: =IF('Success Map'!L27="","",'Success Map'!L27) | R18: =IF('Success Map'!Q27="","",'Success Map'!Q27) | S18: =IF('Success Map'!P27="","",'Success Map'!P27)
I19: =IF('Success Map'!H28="","",'Success Map'!H28) | Q19: =IF('Success Map'!L28="","",'Success Map'!L28) | R19: =IF('Success Map'!Q28="","",'Success Map'!Q28) | S19: =IF('Success Map'!P28="","",'Success Map'!P28)
I20: Test Track
A21: Metric | C21: On-schedule delivery, realized value
I22: ='Success Map'!F34 -> Case | K22: Dates | L22: =IF('Success Map'!H34="","--",'Success Map'!H34) -> Meeting Held | N22: =IF('Success Map'!J34="","--",'Success Map'!J34) -> All Projects Complete | P22: =IF('Success Map'!L34="","--",'Success Map'!L34) -> All Projects report rev. | R22: =IF('Success Map'!N34="","--",'Success Map'!N34) -> -- | T22: =IF('Success Map'!P34="","--",'Success Map'!P34) -> --
A23: Current Perf. | C23: Unknown | I23: =IF('Success Map'!F35="","--",'Success Map'!F35) -> 1st Meeting (12/15) | K23: Plan | L23: 43586 | N23: 43600 | P23: 43607
K24: Replan
K25: Forecast
A26: Targert Perf. | C26: 90% on schedule, generating $2M revenue/year | K26: Actual
I27: =IF('Success Map'!F36="","--",'Success Map'!F36) -> 2nd Meeting (12/18) | K27: Plan | L27: =L23+10 -> 43596 | N27: =N23+10 -> 43610 | P27: =P23+10 -> 43617
K28: Replan
A29: Solve Method | C29: Virtual event with full team, 2-3 hours per day, 5-6 meetings over 2 weeks. | K29: Forecast
K30: Actual
A31: Solve | I31: =IF('Success Map'!F37="","--",'Success Map'!F37) -> 3rd Meeting (1/2) | K31: Plan | L31: =L27+8 -> 43604 | N31: =N27+8 -> 43618 | P31: =P27+8 -> 43625
K32: Replan
A33: Root Cause | C33: No standardized means to review and prioritize/rationalize tasks. No standard measures of value. | K33: Forecast
K34: Actual
I35: =IF('Success Map'!F38="","--",'Success Map'!F38) -> -- | K35: Plan
K36: Replan
K37: Forecast
A38: Solution | C38: Install electronic Kanban board for tasks taken by global team; track value delivered annually | K38: Actual
I39: Bowlers
I41: Goal 1 | J41: ='Success Map'!F47 -> Tasks completed to schedule
A42: Counter Measures | B42: 1 | C42: Install electronic Kanban | I42: Date | J42: ='Success Map'!F46 -> 43466 | K42: =DATE(YEAR(J42),MONTH(J42)+IF('Success Map'!$J$46='Success Map'!$R$44,'Success Map'!$I$46,0),DAY(J42)+IF('Success Map'!$J$46<>'Success Map'!$R$44,'Success Map'!$I$46,0)) -> 43497 | L42: =DATE(YEAR(K42),MONTH(K42)+IF('Success Map'!$J$46='Success Map'!$R$44,'Success Map'!$I$46,0),DAY(K42)+IF('Success Map'!$J$46<>'Success Map'!$R$44,'Success Map'!$I$46,0)) -> 43525 | M42: =DATE(YEAR(L42),MONTH(L42)+IF('Success Map'!$J$46='Success Map'!$R$44,'Success Map'!$I$46,0),DAY(L42)+IF('Success Map'!$J$46<>'Success Map'!$R$44,'Success Map'!$I$46,0)) -> 43556 | N42: =DATE(YEAR(M42),MONTH(M42)+IF('Success Map'!$J$46='Success Map'!$R$44,'Success Map'!$I$46,0),DAY(M42)+IF('Success Map'!$J$46<>'Success Map'!$R$44,'Success Map'!$I$46,0)) -> 43586 | O42: =DATE(YEAR(N42),MONTH(N42)+IF('Success Map'!$J$46='Success Map'!$R$44,'Success Map'!$I$46,0),DAY(N42)+IF('Success Map'!$J$46<>'Success Map'!$R$44,'Success Map'!$I$46,0)) -> 43617 | P42: =DATE(YEAR(O42),MONTH(O42)+IF('Success Map'!$J$46='Success Map'!$R$44,'Success Map'!$I$46,0),DAY(O42)+IF('Success Map'!$J$46<>'Success Map'!$R$44,'Success Map'!$I$46,0)) -> 43647 | Q42: =DATE(YEAR(P42),MONTH(P42)+IF('Success Map'!$J$46='Success Map'!$R$44,'Success Map'!$I$46,0),DAY(P42)+IF('Success Map'!$J$46<>'Success Map'!$R$44,'Success Map'!$I$46,0)) -> 43678 | R42: =DATE(YEAR(Q42),MONTH(Q42)+IF('Success Map'!$J$46='Success Map'!$R$44,'Success Map'!$I$46,0),DAY(Q42)+IF('Success Map'!$J$46<>'Success Map'!$R$44,'Success Map'!$I$46,0)) -> 43709 | ... U42: =DATE(YEAR(T42),MONTH(T42)+IF('Success Map'!$J$46='Success Map'!$R$44,'Success Map'!$I$46,0),DAY(T42)+IF('Success Map'!$J$46<>'Success Map'!$R$44,'Success Map'!$I$46,0)) -> 43800
...

Sheet Success Map
A1: Summary Instructions | U1: 1-New | V1: =IF(Status="",0,INT(LEFT(Status,1))) -> 4
U2: 2-Rdy for Pblm
A3: The success map planning is filled in immediately after a problem solve. The Success Map may not be changed unless renegotiated with the sponsor | U3: 3-Rdy to Solve
U4: 4-Success Map tracking
A5: Values entered here are automatically copied to the Main page of this canvas for tracking
A7: If a Stop-Fix alarm occurs, the team is expected to take all practical steps to protect the dates and goals before starting to renegotiate the plan
A10: A. Action Plan Instructions | H10: Action Plan--Plannning Data | Q10: Start Date
Q11: 43770
A12: 1. Divide the initiative in about 10 steps, roughly equal in complexty. | H12: Deliverable | L12: Owner | M12: # weeks, normal | N12: # weeks, compress (calc) | O12: # weeks, compress | P12: Internal Plan | Q12: Plan
A14: 2. Define a measurable deliverable due at each step. | H14: Define standard work for Kanban | L14: BB | M14: 3 | N14: =IF(M14=0,"",M14*0.8) -> 2.4 | O14: 2.4 | P14: =IF(H14="","",Q11+O14*7) -> 43786.8 | Q14: =IF(H14="","",Q11+M14*7) -> 43791
H15: Pilot 1 | L15: Tucker | M15: 1 | N15: =IF(M15=0,"",M15*0.8) -> 0.8 | O15: 0.8 | P15: =IF(H15="","",P14+O15*7) -> 43792.4 | Q15: =IF(H15="","",Q14+M15*7) -> 43798
A16: 3. Estimate the time to complete each step under "normal" circumstances | H16: Pilot 2 | L16: Tucker | M16: 1 | N16: =IF(M16=0,"",M16*0.8) -> 0.8 | O16: 0.8 | P16: =IF(H16="","",P15+O16*7) -> 43798 | Q16: =IF(H16="","",Q15+M16*7) -> 43805
H17: Train team | L17: BB | M17: 1 | N17: =IF(M17=0,"",M17*0.8) -> 0.8 | O17: 0.8 | P17: =IF(H17="","",P16+O17*7) -> 43803.6 | Q17: =IF(H17="","",Q16+M17*7) -> 43812
A18: 4. Compress each step, on average, about 20% to take out the buffer we automatically insert when estimating "normal" time. | H18: Define standard work for collecting rev by task | L18: BB | M18: 2 | N18: =IF(M18=0,"",M18*0.8) -> 1.6 | O18: 1.6 | P18: =IF(H18="","",P17+O18*7) -> 43814.8 | Q18: =IF(H18="","",Q17+M18*7) -> 43826
H19: Buffer | N19: =IF(M19=0,"",M19*0.8) | O19: 1.6 | P19: =IF(H19="","",P18+O19*7) -> 43826 | Q19: =IF(H19="","",Q18+M19*7) -> 43826
N20: =IF(M20=0,"",M20*0.8) | P20: =IF(H20="","",P19+O20*7) | Q20: =IF(H20="","",Q19+M20*7)
A21: 5. A standard compression is calculated (20%) as a reference | N21: =IF(M21=0,"",M21*0.8) | P21: =IF(H21="","",P20+O21*7) | Q21: =IF(H21="","",Q20+M21*7)
N22: =IF(M22=0,"",M22*0.8) | P22: =IF(H22="","",P21+O22*7) | Q22: =IF(H22="","",Q21+M22*7)
A23: 6. The team should select the actual compressed estimations they can commit to. | N23: =IF(M23=0,"",M23*0.8) | P23: =IF(H23="","",P22+O23*7) | Q23: =IF(H23="","",Q22+M23*7)
N24: =IF(M24=0,"",M24*0.8) | P24: =IF(H24="","",P23+O24*7) | Q24: =IF(H24="","",Q23+M24*7)
N25: =IF(M25=0,"",M25*0.8) | P25: =IF(H25="","",P24+O25*7) | Q25: =IF(H25="","",Q24+M25*7)
A26: 7. Throughout the tracking process, you can use up to a specific amount of buffer to turn off Stop-Fix alarm. | N26: =IF(M26=0,"",M26*0.8) | P26: =IF(H26="","",P25+O26*7) | Q26: =IF(H26="","",Q25+M26*7)
N27: =IF(M27=0,"",M27*0.8) | P27: =IF(H27="","",P26+O27*7) | Q27: =IF(H27="","",Q26+M27*7)
N28: =IF(M28=0,"",M28*0.8) | P28: =IF(H28="","",P27+O28*7) | Q28: =IF(H28="","",Q27+M28*7)
M29: =SUM(M14:M28) -> 8 | N29: =SUM(N14:N28) -> 6.4 | O29: =SUM(O14:O28) -> 8
A32: B. Test Track Plan | F32: Test Track--Planning Data
A34: 1. Identify 3-4 cases the team will follow closely to "watch it work" | F34: Case | H34: Meeting Held | J34: All Projects Complete | L34: All Projects report rev.
F35: 1st Meeting (12/15) | H35: 43814 | J35: 43487 | L35: 43490
A36: 2. Divide "watch it work" into 3-5 makor "Laps" | F36: 2nd Meeting (12/18) | H36: 43817 | J36: 43491 | L36: 43494
F37: 3rd Meeting (1/2) | H37: 43467 | J37: 43496 | L37: 43499
A38: 3. Rename Laps row, e.g., change "Lap 1" to "First prototype ship"
A40: 4. Plan out when each of the "Cases" will complete each "Lap"
A44: C. Bowler Plan | E44: Bowler--Planning Data | R44: Month(s)
R45: Day(s)
A46: 1. Fill in Goal 1 and, optionally Goal 2 | E46: Start on: | F46: 43466 | H46: Cadence | I46: 1 | J46: Month(s)
E47: Goal 1 | F47: Tasks completed to schedule
A48: 2. Select the date to start on. | E48: Date | F48: =B_Start -> 43466 | G48: =DATE(YEAR(F48),MONTH(F48)+IF(B_Units<>$R$45,B_Cadence,0),DAY(F48)+IF(B_Units=$R$45,B_Cadence,0)) -> 43497 | H48: =DATE(YEAR(G48),MONTH(G48)+IF(B_Units<>$R$45,B_Cadence,0),DAY(G48)+IF(B_Units=$R$45,B_Cadence,0)) -> 43525 | I48: =DATE(YEAR(H48),MONTH(H48)+IF(B_Units<>$R$45,B_Cadence,0),DAY(H48)+IF(B_Units=$R$45,B_Cadence,0)) -> 43556 | J48: =DATE(YEAR(I48),MONTH(I48)+IF(B_Units<>$R$45,B_Cadence,0),DAY(I48)+IF(B_Units=$R$45,B_Cadence,0)) -> 43586 | K48: =DATE(YEAR(J48),MONTH(J48)+IF(B_Units<>$R$45,B_Cadence,0),DAY(J48)+IF(B_Units=$R$45,B_Cadence,0)) -> 43617 | L48: =DATE(YEAR(K48),MONTH(K48)+IF(B_Units<>$R$45,B_Cadence,0),DAY(K48)+IF(B_Units=$R$45,B_Cadence,0)) -> 43647 | M48: =DATE(YEAR(L48),MONTH(L48)+IF(B_Units<>$R$45,B_Cadence,0),DAY(L48)+IF(B_Units=$R$45,B_Cadence,0)) -> 43678 | N48: =DATE(YEAR(M48),MONTH(M48)+IF(B_Units<>$R$45,B_Cadence,0),DAY(M48)+IF(B_Units=$R$45,B_Cadence,0)) -> 43709 | ... Q48: =DATE(YEAR(P48),MONTH(P48)+IF(B_Units<>$R$45,B_Cadence,0),DAY(P48)+IF(B_Units=$R$45,B_Cadence,0)) -> 43800
E49: Plan | F49: 0.9 | G49: 0.9 | H49: 0.9 | I49: 0.9 | J49: 0.9 | K49: 0.9 | L49: 0.9 | M49: 0.9 | N49: 0.9 | O49: 0.9 | P49: 0.9 | Q49: 0.9
A50: 3. Select Cadence = time duration of each column
E51: Goal 2 | F51: Revenue earned throughout year
...
